multiprocessing.pool.RemoteTraceback: 
"""
Traceback (most recent call last):
  File "/mpcdf/soft/SLE_12/packages/x86_64/anaconda/3/2020.02/lib/python3.7/multiprocessing/pool.py", line 121, in worker
    result = (True, func(*args, **kwds))
  File "/mpcdf/soft/SLE_12/packages/x86_64/anaconda/3/2020.02/lib/python3.7/multiprocessing/pool.py", line 44, in mapstar
    return list(map(*args))
TypeError: 'NoneType' object is not callable
"""

The above exception was the direct cause of the following exception:

Traceback (most recent call last):
  File "./run.py", line 69, in <module>
    p.map(my_f(np), range(np))
  File "/mpcdf/soft/SLE_12/packages/x86_64/anaconda/3/2020.02/lib/python3.7/multiprocessing/pool.py", line 268, in map
    return self._map_async(func, iterable, mapstar, chunksize).get()
  File "/mpcdf/soft/SLE_12/packages/x86_64/anaconda/3/2020.02/lib/python3.7/multiprocessing/pool.py", line 657, in get
    raise self._value
TypeError: 'NoneType' object is not callable
