/cobra/u/iuyehara/ceci/bash_script/class_network.py:383: RuntimeWarning: invalid value encountered in true_divide
  fitness = fitness/np.sum(fitness)  # fitness values are now normalized
multiprocessing.pool.RemoteTraceback: 
"""
Traceback (most recent call last):
  File "/mpcdf/soft/SLE_12/packages/x86_64/anaconda/3/2020.02/lib/python3.7/multiprocessing/pool.py", line 121, in worker
    result = (True, func(*args, **kwds))
  File "/mpcdf/soft/SLE_12/packages/x86_64/anaconda/3/2020.02/lib/python3.7/multiprocessing/pool.py", line 44, in mapstar
    return list(map(*args))
  File "./run.py", line 103, in my_f
    my_network.refresh_network()
  File "/cobra/u/iuyehara/ceci/bash_script/class_network.py", line 386, in refresh_network
    self.num_nodes, self.num_nodes, p=fitness)
  File "mtrand.pyx", line 922, in numpy.random.mtrand.RandomState.choice
ValueError: probabilities contain NaN
"""

The above exception was the direct cause of the following exception:

Traceback (most recent call last):
  File "./run.py", line 133, in <module>
    p.map(my_f, range(NP))
  File "/mpcdf/soft/SLE_12/packages/x86_64/anaconda/3/2020.02/lib/python3.7/multiprocessing/pool.py", line 268, in map
    return self._map_async(func, iterable, mapstar, chunksize).get()
  File "/mpcdf/soft/SLE_12/packages/x86_64/anaconda/3/2020.02/lib/python3.7/multiprocessing/pool.py", line 657, in get
    raise self._value
ValueError: probabilities contain NaN
