multiprocessing.pool.RemoteTraceback: 
"""
Traceback (most recent call last):
  File "/mpcdf/soft/SLE_12/packages/x86_64/anaconda/3/2020.02/lib/python3.7/multiprocessing/pool.py", line 121, in worker
    result = (True, func(*args, **kwds))
  File "/mpcdf/soft/SLE_12/packages/x86_64/anaconda/3/2020.02/lib/python3.7/multiprocessing/pool.py", line 44, in mapstar
    return list(map(*args))
  File "./run.py", line 83, in my_f
    my_network.interact()
  File "/cobra/u/iuyehara/ceci/bash_script/class_network.py", line 190, in interact
    edge = random.randint(0, self.Max_edges-1)
AttributeError: 'Network' object has no attribute 'Max_edges'
"""

The above exception was the direct cause of the following exception:

Traceback (most recent call last):
  File "./run.py", line 121, in <module>
    p.map(my_f, range(NP))
  File "/mpcdf/soft/SLE_12/packages/x86_64/anaconda/3/2020.02/lib/python3.7/multiprocessing/pool.py", line 268, in map
    return self._map_async(func, iterable, mapstar, chunksize).get()
  File "/mpcdf/soft/SLE_12/packages/x86_64/anaconda/3/2020.02/lib/python3.7/multiprocessing/pool.py", line 657, in get
    raise self._value
AttributeError: 'Network' object has no attribute 'Max_edges'
